<?xml version="1.0" ?>
<robot name="forkbug">

<material name="silver">
  <color rgba="0.700 0.700 0.700 1.000"/>
</material>

<material name="blue">
  <color rgba="0.0 0.0 0.80 1.000"/>
</material>

<material name="black">
  <color rgba="0.05 0.05 0.05 1.000"/>
</material>

<link name="base_link">
  <inertial>
    <origin xyz="0.0 0.03914375028163698 -0.002951658930475545" rpy="0 0 0"/>
    <mass value="4.288473150032987"/>
    <inertia ixx="0.00594449124934697" iyy="0.007311036343050522" izz="0.0036627175340656886" ixy="0.0" iyz="-0.00011778987562060237" ixz="-1.4279066817834971e-18"/>
  </inertial>
  <visual>
    <origin xyz="0 0 0" rpy="0 0 0"/>
    <geometry>
      <mesh filename="meshes/base_link.stl" scale="0.001 0.001 0.001"/>
    </geometry>
    <material name="blue"/>
    <material/>
  </visual>
  <collision>
    <origin xyz="0 0 0" rpy="0 0 0"/>
    <geometry>
      <mesh filename="meshes/base_link.stl" scale="0.001 0.001 0.001"/>
    </geometry>
  </collision>
</link>

<link name="right_wheel1">
  <inertial>
    <origin xyz="0.0075 -4.5426319034494456e-07 -4.4560285050038173e-07" rpy="0 0 0"/>
    <mass value="0.21780549353036396"/>
    <inertia ixx="6.415782787719233e-05" iyy="3.60997630002043e-05" izz="3.609976300020506e-05" ixy="-5.421010862427522e-20" iyz="4.607859233063394e-19" ixz="-5.421010862427522e-20"/>
  </inertial>
  <visual>
    <origin xyz="-0.045 -0.024378 0.028016" rpy="0 0 0"/>
    <geometry>
      <mesh filename="meshes/right_wheel1.stl" scale="0.001 0.001 0.001"/>
    </geometry>
    <material name="black"/>
    <material/>
  </visual>
  <collision>
    <origin xyz="-0.045 -0.024378 0.028016" rpy="0 0 0"/>
    <geometry>
      <mesh filename="meshes/right_wheel1.stl" scale="0.001 0.001 0.001"/>
    </geometry>
  </collision>
</link>

<link name="left_wheel1">
  <inertial>
    <origin xyz="-0.0075 -4.5426319035188345e-07 -4.456028504899734e-07" rpy="0 0 0"/>
    <mass value="0.21780549353036396"/>
    <inertia ixx="6.415782787719238e-05" iyy="3.60997630002043e-05" izz="3.609976300020506e-05" ixy="5.421010862427522e-20" iyz="3.2526065174565133e-19" ixz="0.0"/>
  </inertial>
  <visual>
    <origin xyz="0.045 -0.024378 0.028016" rpy="0 0 0"/>
    <geometry>
      <mesh filename="meshes/left_wheel1.stl" scale="0.001 0.001 0.001"/>
    </geometry>
    <material name="black"/>
    <material/>
  </visual>
  <collision>
    <origin xyz="0.045 -0.024378 0.028016" rpy="0 0 0"/>
    <geometry>
      <mesh filename="meshes/left_wheel1.stl" scale="0.001 0.001 0.001"/>
    </geometry>
  </collision>
</link>

<link name="roller1">
  <inertial>
    <origin xyz="-1.0976815890497881e-07 -0.005219370386680325 0.04000005692506423" rpy="0 0 0"/>
    <mass value="0.07106955168482779"/>
    <inertia ixx="1.893245455488634e-06" iyy="2.1399009148159392e-05" izz="2.081143921714293e-05" ixy="-2.3678730929984176e-12" iyz="1.2279638162424403e-12" ixz="-2.6986940702341474e-11"/>
  </inertial>
  <visual>
    <origin xyz="-0.0 -0.010831 -0.0" rpy="0 0 0"/>
    <geometry>
      <mesh filename="meshes/roller1.stl" scale="0.001 0.001 0.001"/>
    </geometry>
    <material name="black"/>
    <material/>
  </visual>
  <collision>
    <origin xyz="-0.0 -0.010831 -0.0" rpy="0 0 0"/>
    <geometry>
      <mesh filename="meshes/roller1.stl" scale="0.001 0.001 0.001"/>
    </geometry>
  </collision>
</link>

<link name="right_teeth1">
  <inertial>
    <origin xyz="-3.862213383519497e-07 0.004000478393261448 0.02451321833976925" rpy="0 0 0"/>
    <mass value="0.023653717758888238"/>
    <inertia ixx="4.954206968200547e-06" iyy="4.94045189590621e-06" izz="2.3855125046717224e-07" ixy="0.0" iyz="-6.776263578034403e-21" ixz="-1.3552527156068805e-20"/>
  </inertial>
  <visual>
    <origin xyz="-0.020491 -0.01297 -0.044692" rpy="0 0 0"/>
    <geometry>
      <mesh filename="meshes/right_teeth1.stl" scale="0.001 0.001 0.001"/>
    </geometry>
    <material name="silver"/>
    <material/>
  </visual>
  <collision>
    <origin xyz="-0.020491 -0.01297 -0.044692" rpy="0 0 0"/>
    <geometry>
      <mesh filename="meshes/right_teeth1.stl" scale="0.001 0.001 0.001"/>
    </geometry>
  </collision>
</link>

<link name="left_teeth1">
  <inertial>
    <origin xyz="3.862213383658275e-07 0.00400047839326143 0.02451321833976918" rpy="0 0 0"/>
    <mass value="0.023653717758888238"/>
    <inertia ixx="4.954206968200953e-06" iyy="4.9404518959065625e-06" izz="2.3855125046717224e-07" ixy="-1.5924219408380846e-19" iyz="-5.759824041329242e-20" ixz="-2.0328790734103208e-20"/>
  </inertial>
  <visual>
    <origin xyz="0.020491 -0.01297 -0.044692" rpy="0 0 0"/>
    <geometry>
      <mesh filename="meshes/left_teeth1.stl" scale="0.001 0.001 0.001"/>
    </geometry>
    <material name="silver"/>
    <material/>
  </visual>
  <collision>
    <origin xyz="0.020491 -0.01297 -0.044692" rpy="0 0 0"/>
    <geometry>
      <mesh filename="meshes/left_teeth1.stl" scale="0.001 0.001 0.001"/>
    </geometry>
  </collision>
</link>

<joint name="Revolute_1" type="continuous">
  <origin xyz="0.045 0.024378 -0.028016" rpy="0 0 0"/>
  <parent link="base_link"/>
  <child link="right_wheel1"/>
  <axis xyz="1.0 0.0 0.0"/>
</joint>
<transmission name="Revolute_1_tran">
  <type>transmission_interface/SimpleTransmission</type>
  <joint name="Revolute_1">
    <hardwareInterface>PositionJointInterface</hardwareInterface>
  </joint>
  <actuator name="Revolute_1_actr">
    <hardwareInterface>PositionJointInterface</hardwareInterface>
    <mechanicalReduction>1</mechanicalReduction>
  </actuator>
</transmission>

<joint name="Revolute_2" type="continuous">
  <origin xyz="-0.045 0.024378 -0.028016" rpy="0 0 0"/>
  <parent link="base_link"/>
  <child link="left_wheel1"/>
  <axis xyz="1.0 0.0 0.0"/>
</joint>
<transmission name="Revolute_2_tran">
  <type>transmission_interface/SimpleTransmission</type>
  <joint name="Revolute_2">
    <hardwareInterface>PositionJointInterface</hardwareInterface>
  </joint>
  <actuator name="Revolute_2_actr">
    <hardwareInterface>PositionJointInterface</hardwareInterface>
    <mechanicalReduction>1</mechanicalReduction>
  </actuator>
</transmission>

<joint name="Rigid_3" type="fixed">
  <origin xyz="0.0 0.010831 0.0" rpy="0 0 0"/>
  <parent link="base_link"/>
  <child link="roller1"/>
</joint>

<joint name="Revolute_4" type="revolute">
  <origin xyz="0.020491 0.01297 0.044692" rpy="0 0 0"/>
  <parent link="base_link"/>
  <child link="right_teeth1"/>
  <axis xyz="-1.0 0.0 0.0"/>
  <limit upper="1.003564" lower="0.0" effort="100" velocity="100"/>
</joint>
<transmission name="Revolute_4_tran">
  <type>transmission_interface/SimpleTransmission</type>
  <joint name="Revolute_4">
    <hardwareInterface>PositionJointInterface</hardwareInterface>
  </joint>
  <actuator name="Revolute_4_actr">
    <hardwareInterface>PositionJointInterface</hardwareInterface>
    <mechanicalReduction>1</mechanicalReduction>
  </actuator>
</transmission>

<joint name="Revolute_5" type="revolute">
  <origin xyz="-0.020491 0.01297 0.044692" rpy="0 0 0"/>
  <parent link="base_link"/>
  <child link="left_teeth1"/>
  <axis xyz="1.0 0.0 0.0"/>
  <limit upper="0.0" lower="-1.003564" effort="100" velocity="100"/>
</joint>
<transmission name="Revolute_5_tran">
  <type>transmission_interface/SimpleTransmission</type>
  <joint name="Revolute_5">
    <hardwareInterface>PositionJointInterface</hardwareInterface>
  </joint>
  <actuator name="Revolute_5_actr">
    <hardwareInterface>PositionJointInterface</hardwareInterface>
    <mechanicalReduction>1</mechanicalReduction>
  </actuator>
</transmission>

</robot>
